INFO _internal.py:88  * Running on http://127.0.0.1:5000/ (Press CTRL+C to quit)
INFO _internal.py:88  * Restarting with stat
WARNING _internal.py:88  * Debugger is active!
INFO _internal.py:88  * Debugger PIN: 289-544-783
INFO _internal.py:88  * Detected change in '/home/spr/PycharmProject/ihome/ihome/utils/commons.py', reloading
INFO _internal.py:88  * Restarting with stat
INFO _internal.py:88  * Running on http://127.0.0.1:8000/ (Press CTRL+C to quit)
INFO _internal.py:88  * Restarting with stat
WARNING _internal.py:88  * Debugger is active!
INFO _internal.py:88  * Debugger PIN: 289-544-783
INFO _internal.py:88 127.0.0.1 - - [18/Mar/2019 23:17:08] "GET / HTTP/1.1" 200 -
INFO _internal.py:88 127.0.0.1 - - [18/Mar/2019 23:17:09] "GET /static/plugins/bootstrap/css/bootstrap.min.css HTTP/1.1" 200 -
INFO _internal.py:88 127.0.0.1 - - [18/Mar/2019 23:17:09] "GET /static/plugins/font-awesome/css/font-awesome.min.css HTTP/1.1" 200 -
INFO _internal.py:88 127.0.0.1 - - [18/Mar/2019 23:17:09] "GET /static/css/reset.css HTTP/1.1" 200 -
INFO _internal.py:88 127.0.0.1 - - [18/Mar/2019 23:17:09] "GET /static/plugins/swiper/css/swiper.min.css HTTP/1.1" 200 -
INFO _internal.py:88 127.0.0.1 - - [18/Mar/2019 23:17:09] "GET /static/plugins/bootstrap-datepicker/css/bootstrap-datepicker.min.css HTTP/1.1" 200 -
INFO _internal.py:88 127.0.0.1 - - [18/Mar/2019 23:17:09] "GET /static/css/ihome/main.css HTTP/1.1" 200 -
INFO _internal.py:88 127.0.0.1 - - [18/Mar/2019 23:17:09] "GET /static/css/ihome/index.css HTTP/1.1" 200 -
INFO _internal.py:88 127.0.0.1 - - [18/Mar/2019 23:17:09] "GET /static/js/jquery.min.js HTTP/1.1" 200 -
INFO _internal.py:88 127.0.0.1 - - [18/Mar/2019 23:17:09] "GET /static/plugins/bootstrap/js/bootstrap.min.js HTTP/1.1" 200 -
INFO _internal.py:88 127.0.0.1 - - [18/Mar/2019 23:17:09] "GET /static/plugins/swiper/js/swiper.jquery.min.js HTTP/1.1" 200 -
INFO _internal.py:88 127.0.0.1 - - [18/Mar/2019 23:17:09] "GET /static/plugins/bootstrap-datepicker/js/bootstrap-datepicker.min.js HTTP/1.1" 200 -
INFO _internal.py:88 127.0.0.1 - - [18/Mar/2019 23:17:09] "GET /static/plugins/bootstrap-datepicker/locales/bootstrap-datepicker.zh-CN.min.js HTTP/1.1" 200 -
INFO _internal.py:88 127.0.0.1 - - [18/Mar/2019 23:17:09] "GET /static/js/template.js HTTP/1.1" 200 -
INFO _internal.py:88 127.0.0.1 - - [18/Mar/2019 23:17:09] "GET /static/plugins/font-awesome/fonts/fontawesome-webfont.woff2?v=4.6.3 HTTP/1.1" 200 -
INFO _internal.py:88 127.0.0.1 - - [18/Mar/2019 23:17:09] "GET /static/js/ihome/index.js HTTP/1.1" 200 -
INFO _internal.py:88 127.0.0.1 - - [18/Mar/2019 23:17:09] "GET /static/images/logo@128x59.png HTTP/1.1" 200 -
INFO _internal.py:88 127.0.0.1 - - [18/Mar/2019 23:17:10] "GET /api/v1.0/session HTTP/1.1" 404 -
INFO _internal.py:88 127.0.0.1 - - [18/Mar/2019 23:17:10] "GET /api/v1.0/houses/index HTTP/1.1" 404 -
INFO _internal.py:88 127.0.0.1 - - [18/Mar/2019 23:17:10] "GET /api/v1.0/areas HTTP/1.1" 404 -
INFO _internal.py:88 127.0.0.1 - - [18/Mar/2019 23:17:11] "GET /favicon.ico HTTP/1.1" 200 -
INFO _internal.py:88 127.0.0.1 - - [18/Mar/2019 23:17:19] "GET /index HTTP/1.1" 404 -
INFO _internal.py:88 127.0.0.1 - - [18/Mar/2019 23:17:38] "GET /index/ HTTP/1.1" 404 -
INFO _internal.py:88 127.0.0.1 - - [18/Mar/2019 23:17:43] "GET /index.html HTTP/1.1" 200 -
INFO _internal.py:88 127.0.0.1 - - [18/Mar/2019 23:17:44] "GET /api/v1.0/session HTTP/1.1" 404 -
INFO _internal.py:88 127.0.0.1 - - [18/Mar/2019 23:17:44] "GET /api/v1.0/houses/index HTTP/1.1" 404 -
INFO _internal.py:88 127.0.0.1 - - [18/Mar/2019 23:17:44] "GET /api/v1.0/areas HTTP/1.1" 404 -
INFO _internal.py:88 127.0.0.1 - - [18/Mar/2019 23:17:48] "GET /login.html HTTP/1.1" 200 -
INFO _internal.py:88 127.0.0.1 - - [18/Mar/2019 23:17:48] "GET /static/css/ihome/login.css HTTP/1.1" 200 -
INFO _internal.py:88 127.0.0.1 - - [18/Mar/2019 23:17:48] "GET /static/js/ihome/login.js HTTP/1.1" 200 -
INFO _internal.py:88 127.0.0.1 - - [18/Mar/2019 23:17:58] "GET /auth.html HTTP/1.1" 200 -
INFO _internal.py:88 127.0.0.1 - - [18/Mar/2019 23:17:58] "GET /static/css/ihome/profile.css HTTP/1.1" 200 -
INFO _internal.py:88 127.0.0.1 - - [18/Mar/2019 23:17:59] "GET /static/js/jquery.form.min.js HTTP/1.1" 200 -
INFO _internal.py:88 127.0.0.1 - - [18/Mar/2019 23:17:59] "GET /static/js/ihome/auth.js HTTP/1.1" 200 -
INFO _internal.py:88 127.0.0.1 - - [18/Mar/2019 23:17:59] "GET /api/v1.0/users/auth HTTP/1.1" 404 -
INFO _internal.py:88 127.0.0.1 - - [18/Mar/2019 23:18:02] "GET /my.html HTTP/1.1" 200 -
INFO _internal.py:88 127.0.0.1 - - [18/Mar/2019 23:18:02] "GET /static/css/ihome/my.css HTTP/1.1" 200 -
INFO _internal.py:88 127.0.0.1 - - [18/Mar/2019 23:18:02] "GET /static/js/ihome/my.js HTTP/1.1" 200 -
INFO _internal.py:88 127.0.0.1 - - [18/Mar/2019 23:18:02] "GET /api/v1.0/user HTTP/1.1" 404 -
INFO _internal.py:88 127.0.0.1 - - [18/Mar/2019 23:18:05] "GET /api/v1.0/houses/index HTTP/1.1" 404 -
INFO _internal.py:88 127.0.0.1 - - [18/Mar/2019 23:18:05] "GET /api/v1.0/session HTTP/1.1" 404 -
INFO _internal.py:88 127.0.0.1 - - [18/Mar/2019 23:18:05] "GET /api/v1.0/areas HTTP/1.1" 404 -
INFO _internal.py:88 127.0.0.1 - - [18/Mar/2019 23:18:19] "GET /search.html?aid=&aname=&sd=2019-03-23&ed=2019-03-28 HTTP/1.1" 200 -
INFO _internal.py:88 127.0.0.1 - - [18/Mar/2019 23:18:19] "GET /static/css/ihome/search.css HTTP/1.1" 200 -
INFO _internal.py:88 127.0.0.1 - - [18/Mar/2019 23:18:19] "GET /static/js/ihome/search.js HTTP/1.1" 200 -
INFO _internal.py:88 127.0.0.1 - - [18/Mar/2019 23:18:19] "GET /api/v1.0/areas HTTP/1.1" 404 -
INFO _internal.py:88 127.0.0.1 - - [18/Mar/2019 23:18:23] "GET /api/v1.0/houses/index HTTP/1.1" 404 -
INFO _internal.py:88 127.0.0.1 - - [18/Mar/2019 23:18:23] "GET /api/v1.0/session HTTP/1.1" 404 -
INFO _internal.py:88 127.0.0.1 - - [18/Mar/2019 23:18:23] "GET /api/v1.0/areas HTTP/1.1" 404 -
INFO _internal.py:88 127.0.0.1 - - [18/Mar/2019 23:18:31] "GET /search.html?aid=&aname=&sd=2019-03-20&ed= HTTP/1.1" 200 -
INFO _internal.py:88 127.0.0.1 - - [18/Mar/2019 23:18:31] "GET /api/v1.0/areas HTTP/1.1" 404 -
INFO _internal.py:88 127.0.0.1 - - [18/Mar/2019 23:18:42] "GET /api/v1.0/houses?aid=&sd=2019-03-23&ed=2019-03-29&sk=new&p=1 HTTP/1.1" 404 -
INFO _internal.py:88 127.0.0.1 - - [18/Mar/2019 23:18:51] "GET /api/v1.0/houses?aid=&sd=2019-03-23&ed=2019-03-29&sk=price-des&p=1 HTTP/1.1" 404 -
INFO _internal.py:88 127.0.0.1 - - [18/Mar/2019 23:18:51] "GET /api/v1.0/houses/index HTTP/1.1" 404 -
INFO _internal.py:88 127.0.0.1 - - [18/Mar/2019 23:18:51] "GET /api/v1.0/session HTTP/1.1" 404 -
INFO _internal.py:88 127.0.0.1 - - [18/Mar/2019 23:18:51] "GET /api/v1.0/areas HTTP/1.1" 404 -
INFO _internal.py:88  * Running on http://127.0.0.1:8080/ (Press CTRL+C to quit)
INFO _internal.py:88  * Restarting with stat
WARNING _internal.py:88  * Debugger is active!
INFO _internal.py:88  * Debugger PIN: 289-544-783
INFO _internal.py:88 127.0.0.1 - - [19/Mar/2019 12:03:33] "GET /api/v1.0/image_codes/65a53551-1868-43bb-a41f-a8ceb686c5e5 HTTP/1.1" 200 -
INFO _internal.py:88  * Detected change in '/home/spr/PycharmProject/ihome/ihome/api_1_0/vertify_code.py', reloading
INFO _internal.py:88  * Restarting with stat
WARNING _internal.py:88  * Debugger is active!
INFO _internal.py:88  * Debugger PIN: 289-544-783
ERROR vertify_code.py:25 test
INFO _internal.py:88 127.0.0.1 - - [19/Mar/2019 12:06:07] "GET /api/v1.0/image_codes/6c1bbc5d-ccc5-4256-910d-a07b2767d826 HTTP/1.1" 200 -
INFO _internal.py:88  * Detected change in '/home/spr/PycharmProject/ihome/ihome/api_1_0/vertify_code.py', reloading
INFO _internal.py:88  * Restarting with stat
WARNING _internal.py:88  * Debugger is active!
INFO _internal.py:88  * Debugger PIN: 289-544-783
ERROR vertify_code.py:25 test
INFO _internal.py:88 127.0.0.1 - - [19/Mar/2019 12:07:12] "GET /api/v1.0/image_codes/2d5d36c5-20a5-466e-81ea-91c39365c304 HTTP/1.1" 200 -
INFO _internal.py:88  * Detected change in '/home/spr/PycharmProject/ihome/ihome/api_1_0/vertify_code.py', reloading
INFO _internal.py:88  * Restarting with stat
WARNING _internal.py:88  * Debugger is active!
INFO _internal.py:88  * Debugger PIN: 289-544-783
ERROR vertify_code.py:26 test
INFO _internal.py:88 127.0.0.1 - - [19/Mar/2019 12:15:09] "GET /api/v1.0/image_codes/334feb0c-cb99-401e-8fbe-b6e09cdb812d HTTP/1.1" 200 -
INFO _internal.py:88  * Detected change in '/home/spr/PycharmProject/ihome/ihome/api_1_0/vertify_code.py', reloading
INFO _internal.py:88  * Restarting with stat
WARNING _internal.py:88  * Debugger is active!
INFO _internal.py:88  * Debugger PIN: 289-544-783
INFO _internal.py:88  * Detected change in '/home/spr/PycharmProject/ihome/ihome/api_1_0/vertify_code.py', reloading
INFO _internal.py:88  * Restarting with stat
WARNING _internal.py:88  * Debugger is active!
INFO _internal.py:88  * Debugger PIN: 289-544-783
ERROR vertify_code.py:26 test
INFO _internal.py:88 127.0.0.1 - - [19/Mar/2019 12:17:02] "GET /api/v1.0/image_codes/d6f910cd-17ff-4bc1-ae0a-52345da9620d HTTP/1.1" 200 -
ERROR vertify_code.py:26 test
INFO _internal.py:88 127.0.0.1 - - [19/Mar/2019 12:17:03] "GET /api/v1.0/image_codes/ff5cdc54-d9a8-46a8-a41c-b0a669253439 HTTP/1.1" 200 -
INFO _internal.py:88 127.0.0.1 - - [19/Mar/2019 12:17:05] "GET /register.html HTTP/1.1" 304 -
ERROR vertify_code.py:26 test
INFO _internal.py:88 127.0.0.1 - - [19/Mar/2019 12:17:05] "GET /api/v1.0/image_codes/2e0b2cca-8d93-40fe-9939-49d8f67d27eb HTTP/1.1" 200 -
INFO _internal.py:88 127.0.0.1 - - [19/Mar/2019 12:17:05] "GET /favicon.ico HTTP/1.1" 200 -
ERROR vertify_code.py:26 test
INFO _internal.py:88 127.0.0.1 - - [19/Mar/2019 12:17:07] "GET /api/v1.0/image_codes/90308fac-9d37-481c-ba97-18ed2a00cb5f HTTP/1.1" 200 -
INFO _internal.py:88 127.0.0.1 - - [19/Mar/2019 12:17:40] "GET /register.html HTTP/1.1" 200 -
ERROR vertify_code.py:26 test
INFO _internal.py:88 127.0.0.1 - - [19/Mar/2019 12:17:40] "GET /api/v1.0/image_codes/2e0c02f9-f369-4ff2-80bd-76fd0f8a4c61 HTTP/1.1" 200 -
ERROR _internal.py:88 Error on request:
Traceback (most recent call last):
  File "/usr/local/lib/python2.7/dist-packages/werkzeug/serving.py", line 270, in run_wsgi
    execute(self.server.app)
  File "/usr/local/lib/python2.7/dist-packages/werkzeug/serving.py", line 261, in execute
    write(data)
  File "/usr/local/lib/python2.7/dist-packages/werkzeug/serving.py", line 238, in write
    self.send_header('Date', self.date_time_string())
  File "/usr/lib/python2.7/BaseHTTPServer.py", line 412, in send_header
    self.wfile.write("%s: %s\r\n" % (keyword, value))
IOError: [Errno 32] Broken pipe
ERROR vertify_code.py:26 test
INFO _internal.py:88 127.0.0.1 - - [19/Mar/2019 12:17:40] "GET /api/v1.0/image_codes/d2441eb6-e7cd-4a15-8c2b-12fbda8413f2 HTTP/1.1" 200 -
ERROR _internal.py:88 Error on request:
Traceback (most recent call last):
  File "/usr/local/lib/python2.7/dist-packages/werkzeug/serving.py", line 270, in run_wsgi
    execute(self.server.app)
  File "/usr/local/lib/python2.7/dist-packages/werkzeug/serving.py", line 261, in execute
    write(data)
  File "/usr/local/lib/python2.7/dist-packages/werkzeug/serving.py", line 236, in write
    self.send_header('Server', self.version_string())
  File "/usr/lib/python2.7/BaseHTTPServer.py", line 412, in send_header
    self.wfile.write("%s: %s\r\n" % (keyword, value))
IOError: [Errno 32] Broken pipe
INFO _internal.py:88 127.0.0.1 - - [19/Mar/2019 12:17:40] "GET /static/css/reset.css HTTP/1.1" 200 -
INFO _internal.py:88 127.0.0.1 - - [19/Mar/2019 12:17:40] "GET /static/plugins/font-awesome/css/font-awesome.min.css HTTP/1.1" 200 -
INFO _internal.py:88 127.0.0.1 - - [19/Mar/2019 12:17:40] "GET /static/plugins/bootstrap/css/bootstrap.min.css HTTP/1.1" 200 -
INFO _internal.py:88 127.0.0.1 - - [19/Mar/2019 12:17:40] "GET /static/images/logo@128x59.png HTTP/1.1" 200 -
INFO _internal.py:88 127.0.0.1 - - [19/Mar/2019 12:17:40] "GET /static/css/ihome/register.css HTTP/1.1" 200 -
INFO _internal.py:88 127.0.0.1 - - [19/Mar/2019 12:17:40] "GET /static/css/ihome/main.css HTTP/1.1" 200 -
INFO _internal.py:88 127.0.0.1 - - [19/Mar/2019 12:17:40] "GET /static/js/jquery.min.js HTTP/1.1" 200 -
INFO _internal.py:88 127.0.0.1 - - [19/Mar/2019 12:17:40] "GET /static/plugins/bootstrap/js/bootstrap.min.js HTTP/1.1" 200 -
INFO _internal.py:88 127.0.0.1 - - [19/Mar/2019 12:17:40] "GET /static/js/ihome/register.js HTTP/1.1" 200 -
INFO _internal.py:88 127.0.0.1 - - [19/Mar/2019 12:17:40] "GET /static/plugins/font-awesome/fonts/fontawesome-webfont.woff2?v=4.6.3 HTTP/1.1" 200 -
INFO _internal.py:88 127.0.0.1 - - [19/Mar/2019 12:17:40] "GET /static/plugins/bootstrap/css/bootstrap.min.css.map HTTP/1.1" 200 -
ERROR vertify_code.py:26 test
INFO _internal.py:88 127.0.0.1 - - [19/Mar/2019 12:17:40] "GET /api/v1.0/image_codes/6084d689-7635-4bac-a5b1-09ce881b0ae6 HTTP/1.1" 200 -
INFO _internal.py:88 127.0.0.1 - - [19/Mar/2019 12:17:40] "GET /favicon.ico HTTP/1.1" 200 -
INFO _internal.py:88  * Running on http://127.0.0.1:8080/ (Press CTRL+C to quit)
INFO _internal.py:88  * Restarting with stat
WARNING _internal.py:88  * Debugger is active!
INFO _internal.py:88  * Debugger PIN: 289-544-783
ERROR vertify_code.py:26 test
INFO _internal.py:88 127.0.0.1 - - [19/Mar/2019 12:18:47] "GET /api/v1.0/image_codes/66854b6a-d9bb-422c-8d00-f2b7d2265a3f HTTP/1.1" 200 -
ERROR vertify_code.py:26 test
INFO _internal.py:88 127.0.0.1 - - [19/Mar/2019 12:18:49] "GET /api/v1.0/image_codes/9b4340bc-e5e0-46c3-ba24-d526cc1b3099 HTTP/1.1" 200 -
INFO _internal.py:88  * Detected change in '/home/spr/PycharmProject/ihome/ihome/api_1_0/vertify_code.py', reloading
INFO _internal.py:88  * Restarting with stat
WARNING _internal.py:88  * Debugger is active!
INFO _internal.py:88  * Debugger PIN: 289-544-783
INFO _internal.py:88 127.0.0.1 - - [19/Mar/2019 12:19:28] "GET /api/v1.0/image_codes/9fe1583a-58b2-4d1d-a670-616209683f89 HTTP/1.1" 200 -
INFO _internal.py:88  * Detected change in '/home/spr/PycharmProject/ihome/ihome/api_1_0/vertify_code.py', reloading
INFO _internal.py:88  * Restarting with stat
WARNING _internal.py:88  * Debugger is active!
INFO _internal.py:88  * Debugger PIN: 289-544-783
INFO _internal.py:88 127.0.0.1 - - [19/Mar/2019 12:21:04] "GET /api/v1.0/image_codes/4f528146-d3f3-454e-8c5b-9f819e110dd2 HTTP/1.1" 200 -
INFO _internal.py:88  * Detected change in '/home/spr/PycharmProject/ihome/ihome/api_1_0/vertify_code.py', reloading
INFO _internal.py:88  * Restarting with stat
WARNING _internal.py:88  * Debugger is active!
INFO _internal.py:88  * Debugger PIN: 289-544-783
INFO _internal.py:88 127.0.0.1 - - [19/Mar/2019 12:22:55] "GET /api/v1.0/image_codes/e3ebbff1-0510-426e-bcd0-88e546debff3 HTTP/1.1" 200 -
INFO _internal.py:88 127.0.0.1 - - [19/Mar/2019 12:32:09] "GET /api/v1.0/image_codes/e3ebbff1-0510-426e-bcd0-88e546debff3 HTTP/1.1" 200 -
INFO _internal.py:88 127.0.0.1 - - [19/Mar/2019 12:32:40] "GET /api/v1.0/image_codes/e3ebbff1-0510-426e-bcd0-88e546debff3 HTTP/1.1" 200 -
INFO _internal.py:88  * Detected change in '/home/spr/PycharmProject/ihome/ihome/api_1_0/vertify_code.py', reloading
INFO _internal.py:88  * Restarting with stat
WARNING _internal.py:88  * Debugger is active!
INFO _internal.py:88  * Debugger PIN: 289-544-783
INFO _internal.py:88 127.0.0.1 - - [19/Mar/2019 12:33:04] "GET /api/v1.0/image_codes/e3ebbff1-0510-426e-bcd0-88e546debff3 HTTP/1.1" 200 -
INFO _internal.py:88  * Detected change in '/home/spr/PycharmProject/ihome/ihome/api_1_0/vertify_code.py', reloading
INFO _internal.py:88  * Restarting with stat
WARNING _internal.py:88  * Debugger is active!
INFO _internal.py:88  * Debugger PIN: 289-544-783
INFO _internal.py:88  * Detected change in '/home/spr/PycharmProject/ihome/ihome/api_1_0/vertify_code.py', reloading
INFO _internal.py:88  * Restarting with stat
WARNING _internal.py:88  * Debugger is active!
INFO _internal.py:88  * Debugger PIN: 289-544-783
INFO _internal.py:88  * Detected change in '/home/spr/PycharmProject/ihome/ihome/api_1_0/vertify_code.py', reloading
INFO _internal.py:88  * Restarting with stat
WARNING _internal.py:88  * Debugger is active!
INFO _internal.py:88  * Debugger PIN: 289-544-783
INFO _internal.py:88  * Detected change in '/home/spr/PycharmProject/ihome/ihome/api_1_0/vertify_code.py', reloading
INFO _internal.py:88  * Restarting with stat
WARNING _internal.py:88  * Debugger is active!
INFO _internal.py:88  * Debugger PIN: 289-544-783
INFO _internal.py:88  * Detected change in '/home/spr/PycharmProject/ihome/ihome/api_1_0/vertify_code.py', reloading
INFO _internal.py:88  * Restarting with stat
WARNING _internal.py:88  * Debugger is active!
INFO _internal.py:88  * Debugger PIN: 289-544-783
INFO _internal.py:88  * Detected change in '/home/spr/PycharmProject/ihome/ihome/api_1_0/vertify_code.py', reloading
INFO _internal.py:88  * Restarting with stat
WARNING _internal.py:88  * Debugger is active!
INFO _internal.py:88  * Debugger PIN: 289-544-783
INFO _internal.py:88  * Detected change in '/home/spr/PycharmProject/ihome/ihome/api_1_0/vertify_code.py', reloading
INFO _internal.py:88  * Restarting with stat
WARNING _internal.py:88  * Debugger is active!
INFO _internal.py:88  * Debugger PIN: 289-544-783
INFO _internal.py:88  * Detected change in '/home/spr/PycharmProject/ihome/ihome/api_1_0/vertify_code.py', reloading
INFO _internal.py:88  * Restarting with stat
WARNING _internal.py:88  * Debugger is active!
INFO _internal.py:88  * Debugger PIN: 289-544-783
INFO _internal.py:88  * Detected change in '/home/spr/PycharmProject/ihome/ihome/api_1_0/vertify_code.py', reloading
INFO _internal.py:88  * Restarting with stat
WARNING _internal.py:88  * Debugger is active!
INFO _internal.py:88  * Debugger PIN: 289-544-783
INFO _internal.py:88  * Detected change in '/home/spr/PycharmProject/ihome/ihome/api_1_0/vertify_code.py', reloading
INFO _internal.py:88  * Restarting with stat
WARNING _internal.py:88  * Debugger is active!
INFO _internal.py:88  * Debugger PIN: 289-544-783
INFO _internal.py:88  * Detected change in '/home/spr/PycharmProject/ihome/ihome/api_1_0/vertify_code.py', reloading
INFO _internal.py:88  * Restarting with stat
WARNING _internal.py:88  * Debugger is active!
INFO _internal.py:88  * Debugger PIN: 289-544-783
INFO _internal.py:88  * Detected change in '/home/spr/PycharmProject/ihome/ihome/api_1_0/vertify_code.py', reloading
INFO _internal.py:88  * Restarting with stat
WARNING _internal.py:88  * Debugger is active!
INFO _internal.py:88  * Debugger PIN: 289-544-783
INFO _internal.py:88  * Detected change in '/home/spr/PycharmProject/ihome/ihome/api_1_0/vertify_code.py', reloading
INFO _internal.py:88  * Restarting with stat
INFO _internal.py:88  * Running on http://127.0.0.1:8080/ (Press CTRL+C to quit)
INFO _internal.py:88  * Restarting with stat
WARNING _internal.py:88  * Debugger is active!
INFO _internal.py:88  * Debugger PIN: 289-544-783
INFO _internal.py:88 127.0.0.1 - - [19/Mar/2019 15:16:27] "GET /register.html HTTP/1.1" 304 -
INFO _internal.py:88 127.0.0.1 - - [19/Mar/2019 15:16:30] "GET /api/v1.0/image_codes/05573da2-d4ce-43e9-893a-6d56a75453de HTTP/1.1" 200 -
INFO _internal.py:88 127.0.0.1 - - [19/Mar/2019 15:16:30] "GET /favicon.ico HTTP/1.1" 200 -
INFO _internal.py:88  * Detected change in '/home/spr/PycharmProject/ihome/ihome/models.py', reloading
INFO _internal.py:88  * Restarting with stat
WARNING _internal.py:88  * Debugger is active!
INFO _internal.py:88  * Debugger PIN: 289-544-783
INFO log.py:110 SHOW VARIABLES LIKE 'sql_mode'
INFO log.py:110 ()
INFO log.py:110 SHOW VARIABLES LIKE 'lower_case_table_names'
INFO log.py:110 ()
INFO log.py:110 SELECT DATABASE()
INFO log.py:110 ()
INFO log.py:110 show collation where `Charset` = 'utf8mb4' and `Collation` = 'utf8mb4_bin'
INFO log.py:110 ()
INFO log.py:110 SELECT CAST('test plain returns' AS CHAR(60)) AS anon_1
INFO log.py:110 ()
INFO log.py:110 SELECT CAST('test unicode returns' AS CHAR(60)) AS anon_1
INFO log.py:110 ()
INFO log.py:110 SELECT CAST('test collated returns' AS CHAR CHARACTER SET utf8mb4) COLLATE utf8mb4_bin AS anon_1
INFO log.py:110 ()
INFO log.py:110 BEGIN (implicit)
INFO log.py:110 SELECT ih_user_profile.create_time AS ih_user_profile_create_time, ih_user_profile.update_time AS ih_user_profile_update_time, ih_user_profile.id AS ih_user_profile_id, ih_user_profile.name AS ih_user_profile_name, ih_user_profile.password_hash AS ih_user_profile_password_hash, ih_user_profile.mobile AS ih_user_profile_mobile, ih_user_profile.real_name AS ih_user_profile_real_name, ih_user_profile.id_card AS ih_user_profile_id_card, ih_user_profile.avatar_url AS ih_user_profile_avatar_url 
FROM ih_user_profile 
WHERE ih_user_profile.mobile = %s 
 LIMIT %s
INFO log.py:110 ('18888888888', 1)
ERROR vertify_code.py:85 (_mysql_exceptions.ProgrammingError) (1146, "Table 'ihome_01.ih_user_profile' doesn't exist")
[SQL: SELECT ih_user_profile.create_time AS ih_user_profile_create_time, ih_user_profile.update_time AS ih_user_profile_update_time, ih_user_profile.id AS ih_user_profile_id, ih_user_profile.name AS ih_user_profile_name, ih_user_profile.password_hash AS ih_user_profile_password_hash, ih_user_profile.mobile AS ih_user_profile_mobile, ih_user_profile.real_name AS ih_user_profile_real_name, ih_user_profile.id_card AS ih_user_profile_id_card, ih_user_profile.avatar_url AS ih_user_profile_avatar_url 
FROM ih_user_profile 
WHERE ih_user_profile.mobile = %s 
 LIMIT %s]
[parameters: ('18888888888', 1)]
(Background on this error at: http://sqlalche.me/e/f405)
ERROR vertify_code.py:98 setex() takes exactly 4 arguments (5 given)
INFO log.py:110 ROLLBACK
INFO _internal.py:88 127.0.0.1 - - [19/Mar/2019 15:16:56] "GET /api/v1.0/sms_codes/18888888888?image_code=3kmo&image_code_id=05573da2-d4ce-43e9-893a-6d56a75453de HTTP/1.1" 200 -
INFO _internal.py:88 127.0.0.1 - - [19/Mar/2019 15:28:19] "GET /api/v1.0/image_codes/cb16cf57-0781-405e-91e4-c4e0982c3a46 HTTP/1.1" 200 -
INFO log.py:110 BEGIN (implicit)
INFO log.py:110 SELECT ih_user_profile.create_time AS ih_user_profile_create_time, ih_user_profile.update_time AS ih_user_profile_update_time, ih_user_profile.id AS ih_user_profile_id, ih_user_profile.name AS ih_user_profile_name, ih_user_profile.password_hash AS ih_user_profile_password_hash, ih_user_profile.mobile AS ih_user_profile_mobile, ih_user_profile.real_name AS ih_user_profile_real_name, ih_user_profile.id_card AS ih_user_profile_id_card, ih_user_profile.avatar_url AS ih_user_profile_avatar_url 
FROM ih_user_profile 
WHERE ih_user_profile.mobile = %s 
 LIMIT %s
INFO log.py:110 ('18888888888', 1)
ERROR vertify_code.py:85 (_mysql_exceptions.ProgrammingError) (1146, "Table 'ihome_01.ih_user_profile' doesn't exist")
[SQL: SELECT ih_user_profile.create_time AS ih_user_profile_create_time, ih_user_profile.update_time AS ih_user_profile_update_time, ih_user_profile.id AS ih_user_profile_id, ih_user_profile.name AS ih_user_profile_name, ih_user_profile.password_hash AS ih_user_profile_password_hash, ih_user_profile.mobile AS ih_user_profile_mobile, ih_user_profile.real_name AS ih_user_profile_real_name, ih_user_profile.id_card AS ih_user_profile_id_card, ih_user_profile.avatar_url AS ih_user_profile_avatar_url 
FROM ih_user_profile 
WHERE ih_user_profile.mobile = %s 
 LIMIT %s]
[parameters: ('18888888888', 1)]
(Background on this error at: http://sqlalche.me/e/f405)
ERROR vertify_code.py:98 setex() takes exactly 4 arguments (5 given)
INFO log.py:110 ROLLBACK
INFO _internal.py:88 127.0.0.1 - - [19/Mar/2019 15:28:25] "GET /api/v1.0/sms_codes/18888888888?image_code=gy3v&image_code_id=cb16cf57-0781-405e-91e4-c4e0982c3a46 HTTP/1.1" 200 -
INFO _internal.py:88 127.0.0.1 - - [19/Mar/2019 15:29:05] "GET /api/v1.0/sms_codes/18888888888?image_code=gy3v&image_code_id=cb16cf57-0781-405e-91e4-c4e0982c3a46 HTTP/1.1" 200 -
INFO _internal.py:88 127.0.0.1 - - [19/Mar/2019 15:29:08] "GET /api/v1.0/image_codes/788fce98-c40a-4b77-ba14-6000bda27e23 HTTP/1.1" 200 -
INFO log.py:110 BEGIN (implicit)
INFO log.py:110 SELECT ih_user_profile.create_time AS ih_user_profile_create_time, ih_user_profile.update_time AS ih_user_profile_update_time, ih_user_profile.id AS ih_user_profile_id, ih_user_profile.name AS ih_user_profile_name, ih_user_profile.password_hash AS ih_user_profile_password_hash, ih_user_profile.mobile AS ih_user_profile_mobile, ih_user_profile.real_name AS ih_user_profile_real_name, ih_user_profile.id_card AS ih_user_profile_id_card, ih_user_profile.avatar_url AS ih_user_profile_avatar_url 
FROM ih_user_profile 
WHERE ih_user_profile.mobile = %s 
 LIMIT %s
INFO log.py:110 ('18888888888', 1)
ERROR vertify_code.py:85 (_mysql_exceptions.ProgrammingError) (1146, "Table 'ihome_01.ih_user_profile' doesn't exist")
[SQL: SELECT ih_user_profile.create_time AS ih_user_profile_create_time, ih_user_profile.update_time AS ih_user_profile_update_time, ih_user_profile.id AS ih_user_profile_id, ih_user_profile.name AS ih_user_profile_name, ih_user_profile.password_hash AS ih_user_profile_password_hash, ih_user_profile.mobile AS ih_user_profile_mobile, ih_user_profile.real_name AS ih_user_profile_real_name, ih_user_profile.id_card AS ih_user_profile_id_card, ih_user_profile.avatar_url AS ih_user_profile_avatar_url 
FROM ih_user_profile 
WHERE ih_user_profile.mobile = %s 
 LIMIT %s]
[parameters: ('18888888888', 1)]
(Background on this error at: http://sqlalche.me/e/f405)
ERROR vertify_code.py:98 setex() takes exactly 4 arguments (5 given)
INFO log.py:110 ROLLBACK
INFO _internal.py:88 127.0.0.1 - - [19/Mar/2019 15:29:15] "GET /api/v1.0/sms_codes/18888888888?image_code=cG7v&image_code_id=788fce98-c40a-4b77-ba14-6000bda27e23 HTTP/1.1" 200 -
INFO _internal.py:88  * Detected change in '/home/spr/PycharmProject/ihome/ihome/api_1_0/vertify_code.py', reloading
INFO _internal.py:88  * Restarting with stat
WARNING _internal.py:88  * Debugger is active!
INFO _internal.py:88  * Debugger PIN: 289-544-783
INFO _internal.py:88  * Detected change in '/home/spr/PycharmProject/ihome/ihome/api_1_0/vertify_code.py', reloading
INFO _internal.py:88  * Restarting with stat
WARNING _internal.py:88  * Debugger is active!
INFO _internal.py:88  * Debugger PIN: 289-544-783
INFO _internal.py:88 127.0.0.1 - - [19/Mar/2019 15:31:56] "GET /api/v1.0/image_codes/224335ea-b160-45b2-a28e-455b081cbfe8 HTTP/1.1" 200 -
INFO log.py:110 SHOW VARIABLES LIKE 'sql_mode'
INFO log.py:110 ()
INFO log.py:110 SHOW VARIABLES LIKE 'lower_case_table_names'
INFO log.py:110 ()
INFO log.py:110 SELECT DATABASE()
INFO log.py:110 ()
INFO log.py:110 show collation where `Charset` = 'utf8mb4' and `Collation` = 'utf8mb4_bin'
INFO log.py:110 ()
INFO log.py:110 SELECT CAST('test plain returns' AS CHAR(60)) AS anon_1
INFO log.py:110 ()
INFO log.py:110 SELECT CAST('test unicode returns' AS CHAR(60)) AS anon_1
INFO log.py:110 ()
INFO log.py:110 SELECT CAST('test collated returns' AS CHAR CHARACTER SET utf8mb4) COLLATE utf8mb4_bin AS anon_1
INFO log.py:110 ()
INFO log.py:110 BEGIN (implicit)
INFO log.py:110 SELECT ih_user_profile.create_time AS ih_user_profile_create_time, ih_user_profile.update_time AS ih_user_profile_update_time, ih_user_profile.id AS ih_user_profile_id, ih_user_profile.name AS ih_user_profile_name, ih_user_profile.password_hash AS ih_user_profile_password_hash, ih_user_profile.mobile AS ih_user_profile_mobile, ih_user_profile.real_name AS ih_user_profile_real_name, ih_user_profile.id_card AS ih_user_profile_id_card, ih_user_profile.avatar_url AS ih_user_profile_avatar_url 
FROM ih_user_profile 
WHERE ih_user_profile.mobile = %s 
 LIMIT %s
INFO log.py:110 ('18888888888', 1)
ERROR vertify_code.py:85 (_mysql_exceptions.ProgrammingError) (1146, "Table 'ihome_01.ih_user_profile' doesn't exist")
[SQL: SELECT ih_user_profile.create_time AS ih_user_profile_create_time, ih_user_profile.update_time AS ih_user_profile_update_time, ih_user_profile.id AS ih_user_profile_id, ih_user_profile.name AS ih_user_profile_name, ih_user_profile.password_hash AS ih_user_profile_password_hash, ih_user_profile.mobile AS ih_user_profile_mobile, ih_user_profile.real_name AS ih_user_profile_real_name, ih_user_profile.id_card AS ih_user_profile_id_card, ih_user_profile.avatar_url AS ih_user_profile_avatar_url 
FROM ih_user_profile 
WHERE ih_user_profile.mobile = %s 
 LIMIT %s]
[parameters: ('18888888888', 1)]
(Background on this error at: http://sqlalche.me/e/f405)
INFO log.py:110 ROLLBACK
INFO _internal.py:88 127.0.0.1 - - [19/Mar/2019 15:32:04] "GET /api/v1.0/sms_codes/18888888888?image_code=E4tg&image_code_id=224335ea-b160-45b2-a28e-455b081cbfe8 HTTP/1.1" 200 -
INFO _internal.py:88  * Detected change in '/home/spr/PycharmProject/ihome/ihome/api_1_0/vertify_code.py', reloading
INFO _internal.py:88  * Restarting with stat
WARNING _internal.py:88  * Debugger is active!
INFO _internal.py:88  * Debugger PIN: 289-544-783
INFO _internal.py:88 127.0.0.1 - - [19/Mar/2019 15:33:12] "GET /api/v1.0/image_codes/c632e431-938a-4844-a184-e2231eea11ca HTTP/1.1" 200 -
INFO log.py:110 SHOW VARIABLES LIKE 'sql_mode'
INFO log.py:110 ()
INFO log.py:110 SHOW VARIABLES LIKE 'lower_case_table_names'
INFO log.py:110 ()
INFO log.py:110 SELECT DATABASE()
INFO log.py:110 ()
INFO log.py:110 show collation where `Charset` = 'utf8mb4' and `Collation` = 'utf8mb4_bin'
INFO log.py:110 ()
INFO log.py:110 SELECT CAST('test plain returns' AS CHAR(60)) AS anon_1
INFO log.py:110 ()
INFO log.py:110 SELECT CAST('test unicode returns' AS CHAR(60)) AS anon_1
INFO log.py:110 ()
INFO log.py:110 SELECT CAST('test collated returns' AS CHAR CHARACTER SET utf8mb4) COLLATE utf8mb4_bin AS anon_1
INFO log.py:110 ()
INFO log.py:110 BEGIN (implicit)
INFO log.py:110 SELECT ih_user_profile.create_time AS ih_user_profile_create_time, ih_user_profile.update_time AS ih_user_profile_update_time, ih_user_profile.id AS ih_user_profile_id, ih_user_profile.name AS ih_user_profile_name, ih_user_profile.password_hash AS ih_user_profile_password_hash, ih_user_profile.mobile AS ih_user_profile_mobile, ih_user_profile.real_name AS ih_user_profile_real_name, ih_user_profile.id_card AS ih_user_profile_id_card, ih_user_profile.avatar_url AS ih_user_profile_avatar_url 
FROM ih_user_profile 
WHERE ih_user_profile.mobile = %s 
 LIMIT %s
INFO log.py:110 ('18888888888', 1)
ERROR vertify_code.py:85 (_mysql_exceptions.ProgrammingError) (1146, "Table 'ihome_01.ih_user_profile' doesn't exist")
[SQL: SELECT ih_user_profile.create_time AS ih_user_profile_create_time, ih_user_profile.update_time AS ih_user_profile_update_time, ih_user_profile.id AS ih_user_profile_id, ih_user_profile.name AS ih_user_profile_name, ih_user_profile.password_hash AS ih_user_profile_password_hash, ih_user_profile.mobile AS ih_user_profile_mobile, ih_user_profile.real_name AS ih_user_profile_real_name, ih_user_profile.id_card AS ih_user_profile_id_card, ih_user_profile.avatar_url AS ih_user_profile_avatar_url 
FROM ih_user_profile 
WHERE ih_user_profile.mobile = %s 
 LIMIT %s]
[parameters: ('18888888888', 1)]
(Background on this error at: http://sqlalche.me/e/f405)
INFO log.py:110 ROLLBACK
INFO _internal.py:88 127.0.0.1 - - [19/Mar/2019 15:33:19] "GET /api/v1.0/sms_codes/18888888888?image_code=Yatp&image_code_id=c632e431-938a-4844-a184-e2231eea11ca HTTP/1.1" 200 -
INFO _internal.py:88  * Detected change in '/home/spr/PycharmProject/ihome/ihome/api_1_0/vertify_code.py', reloading
INFO _internal.py:88  * Restarting with stat
WARNING _internal.py:88  * Debugger is active!
INFO _internal.py:88  * Debugger PIN: 289-544-783
INFO _internal.py:88  * Detected change in '/home/spr/PycharmProject/ihome/ihome/api_1_0/vertify_code.py', reloading
INFO _internal.py:88  * Restarting with stat
WARNING _internal.py:88  * Debugger is active!
INFO _internal.py:88  * Debugger PIN: 289-544-783
INFO _internal.py:88  * Detected change in '/home/spr/PycharmProject/ihome/ihome/models.py', reloading
INFO _internal.py:88  * Restarting with stat
WARNING _internal.py:88  * Debugger is active!
INFO _internal.py:88  * Debugger PIN: 289-544-783
INFO _internal.py:88  * Detected change in '/home/spr/PycharmProject/ihome/ihome/models.py', reloading
INFO _internal.py:88  * Restarting with stat
WARNING _internal.py:88  * Debugger is active!
INFO _internal.py:88  * Debugger PIN: 289-544-783
ERROR __init__.py:97 Error: Directory migrations already exists
INFO _internal.py:88  * Detected change in '/home/spr/PycharmProject/ihome/ihome/constants.py', reloading
INFO _internal.py:88  * Restarting with stat
WARNING _internal.py:88  * Debugger is active!
INFO _internal.py:88  * Debugger PIN: 289-544-783
